Workbook

Sheet LUS - Pipes
A1: Pipe ID | B1: Installed | C1: Diameter [inch] | D1: Distance until highest point [km] | E1: Longitude [km] | F1: Node connections | G1: Node types | H1: Initial pressure [bar] | I1: Pressure at highest point [bar] | J1: Final pressure [bar] | K1: Lowest pressure [bar] | L1: Initial temperature [°C] | M1: Temperature at critical pressure point [°C] | N1: Final temperature [°C] | O1: Lowest temperature [°C] | P1: Number of boosters | Q1: Booster installation year | R1: Installation Year | S1: Present Value Cost [M€] | T1: Insulated | U1: U-value [W/m^2/K] | V1: Insulation cost [M€] | W1: Booster delta pressure [bar] | X1: Booster delta temperature [°C] | Y1: Flow in 2030 | Z1: Flow in 2035 | AA1: Flow in 2040 | AB1: Flow in 2045 | AC1: Flow in 2050
A2: 25_a | B2: 1 | C2: 38 | D2: 186.05 | E2: 297.08 | F2: (16, 27) | G2: ('E', 'A') | H2: 150 | I2: 87.381501 | J2: 229.19293 | K2: 87.381501 | L2: 45 | M2: 27.095937 | N2: 40.276309 | O2: 27.123708 | P2: 1 | Q2: 2040 | R2: 2040 | S2: 409.55101 | T2: FALSE | U2: 2 | V2: 0 | W2: 50 | X2: 10 | Y2: 0 | Z2: 0 | AA2: 92.246 | AB2: 107.39 | AC2: 110.85
A3: 60_a | B3: 0 | D3: 84.57 | E3: 127.1 | F3: (6, 21) | G3: ('K', 'S') | T3: FALSE
A4: 1_a | B4: 0 | D4: 350.21 | E4: 491.3 | F4: (19, 27) | G4: ('S', 'A') | T4: FALSE
A5: 9_a | B5: 0 | D5: 482.28 | E5: 484.78 | F5: (15, 23) | G5: ('E', 'S') | T5: FALSE
A6: 57_b | B6: 0 | D6: 85.12 | E6: 166.23 | F6: (28, 21) | G6: ('A', 'S') | T6: FALSE
A7: 56_b | B7: 0 | D7: 222.78 | E7: 263.83 | F7: (18, 15) | G7: ('E', 'E') | T7: FALSE
A8: 9_b | B8: 0 | D8: 2.5 | E8: 484.78 | F8: (23, 15) | G8: ('S', 'E') | T8: FALSE
A9: 25_b | B9: 0 | D9: 109.53 | E9: 297.08 | F9: (27, 16) | G9: ('A', 'E') | T9: FALSE
A10: 28_a | B10: 0 | D10: 207.57 | E10: 496.16 | F10: (13, 16) | G10: ('E', 'E') | T10: FALSE
A11: 10_b | B11: 0 | D11: 132.71 | E11: 141.73 | F11: (22, 18) | G11: ('S', 'E') | T11: FALSE
A12: 70_a | B12: 0 | D12: 64.08 | E12: 369.46 | F12: (16, 19) | G12: ('E', 'S') | T12: FALSE
A13: 67_b | B13: 0 | D13: 85.34 | E13: 110.44 | F13: (26, 11) | G13: ('A', 'E') | T13: FALSE
A14: 34_b | B14: 0 | D14: 200.08 | E14: 553.72 | F14: (12, 11) | G14: ('E', 'E') | T14: FALSE
... A37: 41_a | B37: 0 | D37: 0 | E37: 100.6 | F37: (12, 20) | G37: ('E', 'S') | T37: FALSE
A38: 5_a | B38: 1 | C38: 30 | D38: 65.69 | E38: 80.23 | F38: (13, 23) | G38: ('E', 'S') | H38: 150 | I38: 113.38214 | J38: 142.06171 | K38: 113.38214 | L38: 45 | M38: 35.774081 | N38: 37.353685 | O38: 35.145913 | P38: 0 | R38: 2035 | S38: 115.19613 | T38: FALSE | U38: 2 | V38: 0 | Y38: 0 | Z38: 57.46 | AA38: 60.52 | AB38: 63.92 | AC38: 67.67
A39: 7_b | B39: 0 | D39: 167.02 | E39: 518.06 | F39: (17, 6) | G39: ('E', 'K') | T39: FALSE
A40: 14_a | B40: 1 | C40: 26 | D40: 147.03 | E40: 222.05 | F40: (10, 21) | G40: ('E', 'S') | H40: 150 | I40: 78.24019 | J40: 141.68952 | K40: 78.24019 | L40: 45 | M40: 32.339456 | N40: 43.137131 | O40: 31.64011 | P40: 1 | Q40: 2045 | R40: 2045 | S40: 223.74704 | T40: TRUE | U40: 0.43 | V40: 63.927725 | W40: 50 | X40: 10 | Y40: 0 | Z40: 0 | AA40: 0 | AB40: 36.8195 | AC40: 55.110648
A41: 16_a | B41: 0 | D41: 30.51 | E41: 555.74 | F41: (12, 27) | G41: ('E', 'A') | T41: FALSE
A42: 37_b | B42: 0 | D42: 86.53 | E42: 347.61 | F42: (24, 5) | G42: ('S', 'K') | T42: FALSE
A43: 47_a | B43: 0 | D43: 31.51 | E43: 562.63 | F43: (12, 26) | G43: ('E', 'A') | T43: FALSE
A44: 0_b | B44: 0 | D44: 121.13 | E44: 423.46 | F44: (5, 4) | G44: ('K', 'K') | T44: FALSE
A45: 0_a | B45: 0 | D45: 302.33 | E45: 423.46 | F45: (4, 5) | G45: ('K', 'K') | T45: FALSE
A46: 17_a | B46: 0 | D46: 295.43 | E46: 336.49 | F46: (11, 25) | G46: ('E', 'A') | T46: FALSE
A47: 26_a | B47: 0 | D47: 129.2 | E47: 263.91 | F47: (19, 23) | G47: ('S', 'S') | T47: FALSE
A48: 30_a | B48: 0 | D48: 44.01 | E48: 243.08 | F48: (13, 19) | G48: ('E', 'S') | T48: FALSE
A49: 3_b | B49: 1 | C49: 34 | D49: 57.79 | E49: 68.85 | F49: (17, 4) | G49: ('E', 'K') | H49: 150 | I49: 138.18312 | J49: 143.13227 | K49: 138.18312 | L49: 45 | M49: 39.013584 | N49: 38.693962 | O49: 38.535901 | P49: 0 | R49: 2045 | S49: 61.923116 | T49: FALSE | U49: 2 | V49: 0 | Y49: 0 | Z49: 0 | AA49: 0 | AB49: 74.21 | AC49: 75
A50: 32_a | B50: 0 | D50: 303.66 | E50: 345.18 | F50: (5, 21) | G50: ('K', 'S') | T50: FALSE
A51: 49_b | B51: 0 | D51: 48.51 | E51: 302.06 | F51: (25, 17) | G51: ('A', 'E') | T51: FALSE
A52: 47_b | B52: 0 | D52: 530.62 | E52: 562.63 | F52: (26, 12) | G52: ('A', 'E') | T52: FALSE
A53: 31_b | B53: 0 | D53: 142.8 | E53: 228.48 | F53: (22, 15) | G53: ('S', 'E') | T53: FALSE
A54: 2_b | B54: 0 | D54: 328.74 | E54: 448.83 | F54: (11, 4) | G54: ('E', 'K') | T54: FALSE
A55: 4_b | B55: 1 | C55: 30 | D55: 51.62 | E55: 151.35 | F55: (14, 6) | G55: ('E', 'K') | H55: 150 | I55: 105.252 | J55: 195.26472 | K55: 105.252 | L55: 45 | M55: 35.051578 | N55: 34.118409 | O55: 33.907369 | P55: 0 | R55: 2035 | S55: 212.96981 | T55: FALSE | U55: 2 | V55: 0 | Y55: 0 | Z55: 27.132 | AA55: 34.686 | AB55: 0 | AC55: 37.172148
A56: 37_a | B56: 0 | D56: 261.08 | E56: 347.61 | F56: (5, 24) | G56: ('K', 'S') | T56: FALSE
A57: 64_a | B57: 0 | D57: 222.05 | E57: 245.06 | F57: (17, 24) | G57: ('E', 'S') | T57: FALSE
A58: 44_b | B58: 0 | D58: 258.27 | E58: 348.87 | F58: (23, 12) | G58: ('S', 'E') | T58: FALSE
A59: 40_b | B59: 0 | D59: 209.77 | E59: 326.42 | F59: (21, 20) | G59: ('S', 'S') | T59: FALSE
A60: 62_b | B60: 0 | D60: 61.67 | E60: 147.41 | F60: (22, 10) | G60: ('S', 'E') | T60: FALSE
A61: 36_a | B61: 0 | D61: 77.08 | E61: 325.83 | F61: (10, 20) | G61: ('E', 'S') | T61: FALSE
A62: 5_b | B62: 0 | D62: 14.54 | E62: 80.23 | F62: (23, 13) | G62: ('S', 'E') | T62: FALSE
...

Sheet LUS - Sinks capacity evolution
A1: Sink node | B1: Initial capacity [Mt] | C1: 2030 capacity [Mt] | D1: 2035 capacity [Mt] | E1: 2040 capacity [Mt] | F1: 2045 capacity [Mt] | G1: 2050 capacity [Mt] | H1: Final capacity [Mt]
A2: 1 | B2: 1250 | C2: 1250 | D2: 1250 | E2: 1250 | F2: 1250 | G2: 1250 | H2: 1250
A3: 2 | B3: 3790 | C3: 3790 | D3: 3790 | E3: 3658.496 | F3: 3527.166 | G3: 3398.706 | H3: 3271.636
A4: 3 | B4: 2100 | C4: 2100 | D4: 2100 | E4: 2100 | F4: 2007.754 | G4: 1900.364 | H4: 1789.514
A5: 19 | B5: 6655.37 | C5: 6655.37 | D5: 6655.37 | E5: 6655.37 | F5: 6655.37 | G5: 6655.37 | H5: 6655.37
A6: 20 | B6: 4571.37 | C6: 4571.37 | D6: 4571.37 | E6: 4571.37 | F6: 4571.37 | G6: 4571.37 | H6: 4571.37
A7: 21 | B7: 1372.72 | C7: 1372.72 | D7: 1323.17 | E7: 1299.572 | F7: 1281.998 | G7: 1191.0585 | H7: 1116.8
A8: 22 | B8: 2171.48 | C8: 2171.48 | D8: 2151.842 | E8: 2151.842 | F8: 2124.232 | G8: 2095.722 | H8: 1993.092
A9: 23 | B9: 4632.05 | C9: 4632.05 | D9: 4632.05 | E9: 4574.59 | F9: 4514.07 | G9: 4450.15 | H9: 4382.48
A10: 24 | B10: 1319.75 | C10: 1319.75 | D10: 1319.75 | E10: 1319.75 | F10: 1319.75 | G10: 1319.75 | H10: 1319.75

Sheet LUS - Utilization evolution
A1: Utilization node | B1: Utilization capacity [Mt] | C1: 2030 utilization [Mt] | D1: 2035 utilization [Mt] | E1: 2040 utilization [Mt] | F1: 2045 utilization [Mt] | G1: 2050 utilization [Mt]
A2: 4 | B2: 75 | C2: 0 | D2: 0 | E2: 0 | F2: 74.21 | G2: 75
A3: 5 | B3: 37.5 | C3: 0 | D3: 0 | E3: 25.8 | F3: 25.8265 | G3: 28.2
A4: 6 | B4: 37.5 | C4: 0 | D4: 27.132 | E4: 34.686 | F4: 0 | G4: 37.172148

Sheet LUS - Cost breakdown
A1: Concept | B1: 2030 | C1: 2035 | D1: 2040 | E1: 2045 | F1: 2050 | G1: Total
A2: Capture cost | B2: 5288.0388 | C2: 13885.473 | D2: 17114.625 | E2: 17286.032 | F2: 15714.522 | G2: 69288.691
A3: Injection cost | B3: 453.1814 | C3: 1054.3075 | D3: 1241.3856 | E3: 1194.7756 | F3: 1042.1536 | G3: 4985.8037
A4: CAPEX onshore pipe | B4: 677.888 | C4: 544.46419 | D4: 479.56211 | E4: 285.67015 | F4: 445.3684 | G4: 2432.9528
A5: CAPEX onshore pipe (insulation only) | B5: 193.68229 | C5: 0 | D5: 0 | E5: 63.927725 | F5: 57.531404 | G5: 315.14141
A6: CAPEX offshore pipe | B6: 0 | C6: 98.422962 | D6: 66.686421 | E6: 0 | F6: 0 | G6: 165.10938
A7: CAPEX initial boosting stations | B7: 4983.8968 | C7: 9224.8657 | D7: 4634.8146 | E7: 3484.4341 | F7: 1398.8621 | G7: 23726.873
A8: CAPEX additional boosting stations | B8: 0 | C8: 0 | D8: 247.333 | E8: 87.736152 | F8: 249.93657 | G8: 585.00573
A9: OPEX onshore pipe | B9: 88.125663 | C9: 137.58001 | D9: 166.6277 | E9: 163.44101 | F9: 181.78759 | G9: 737.56196
A10: OPEX onshore pipe (insulation only) | B10: 25.178761 | C10: 19.085565 | D10: 14.466645 | E10: 19.276042 | F10: 22.090862 | G10: 100.09787
A11: OPEX offshore pipe | B11: 0 | C11: 12.795014 | D11: 18.367903 | E11: 13.9229 | F11: 10.553524 | G11: 55.639341
A12: OPEX initial boosting stations | B12: 134.62097 | C12: 351.27972 | D12: 391.266 | E12: 390.5473 | F12: 333.82173 | G12: 1601.5357
A13: OPEX additional boosting stations | B13: 0 | C13: 0 | D13: 6.3569644 | E13: 7.0861206 | F13: 11.777048 | G13: 25.220133
... A19: TOTAL | B19: 57951.884 | C19: 50625.666 | D19: 36798.115 | E19: 28561.359 | F19: 18187.898 | G19: 192124.92

Sheet EUS - Pipes
A1: Pipe ID | B1: Length [km] | C1: Installed | D1: Diameter [inch] | E1: Distance until highest point [km] | F1: Longitude [km] | G1: Node connections | H1: Node types | I1: Initial pressure [bar] | J1: Pressure at highest point [bar] | K1: Final pressure [bar] | L1: Lowest pressure [bar] | M1: Initial temperature [°C] | N1: Temperature at critical pressure point [°C] | O1: Final temperature [°C] | P1: Lowest temperature [°C] | Q1: Number of boosters | R1: Booster installation year | S1: Installation Year | T1: Present Value Cost [M€] | U1: Insulated | V1: U-value [W/m^2/K] | W1: Insulation cost [M€] | X1: Booster delta pressure [bar] | Y1: Booster delta temperature [°C] | Z1: Flow in 2030 | AA1: Flow in 2035 | AB1: Flow in 2040 | AC1: Flow in 2045 | AD1: Flow in 2050
A2: 25_a | B2: =VLOOKUP(A2,PIPE!A:D,4,0) -> 297.08 | C2: 1 | D2: 38 | E2: 186.05 | F2: 297.08 | G2: (16, 27) | H2: ('E', 'A') | I2: 150 | J2: 87.381501 | K2: 229.19293 | L2: 87.381501 | M2: 45 | N2: 27.095937 | O2: 40.276309 | P2: 27.123708 | Q2: 1 | R2: 2040 | S2: 2040 | T2: 409.55101 | U2: FALSE | V2: 2 | W2: 0 | X2: 50 | Y2: 10 | Z2: 0 | AA2: 0 | AB2: 104.64 | AC2: 107.39 | AD2: 110.85
A3: 60_a | B3: =VLOOKUP(A3,PIPE!A:D,4,0) -> 127.1 | C3: 0 | E3: 84.57 | F3: 127.1 | G3: (6, 21) | H3: ('K', 'S') | U3: FALSE
A4: 1_a | B4: =VLOOKUP(A4,PIPE!A:D,4,0) -> 491.3 | C4: 0 | E4: 350.21 | F4: 491.3 | G4: (19, 27) | H4: ('S', 'A') | U4: FALSE
A5: 9_a | B5: =VLOOKUP(A5,PIPE!A:D,4,0) -> 484.78 | C5: 0 | E5: 482.28 | F5: 484.78 | G5: (15, 23) | H5: ('E', 'S') | U5: FALSE
A6: 57_b | B6: =VLOOKUP(A6,PIPE!A:D,4,0) -> 166.23 | C6: 0 | E6: 85.12 | F6: 166.23 | G6: (28, 21) | H6: ('A', 'S') | U6: FALSE
A7: 56_b | B7: =VLOOKUP(A7,PIPE!A:D,4,0) -> 263.83 | C7: 0 | E7: 222.78 | F7: 263.83 | G7: (18, 15) | H7: ('E', 'E') | U7: FALSE
A8: 9_b | B8: =VLOOKUP(A8,PIPE!A:D,4,0) -> 484.78 | C8: 0 | E8: 2.5 | F8: 484.78 | G8: (23, 15) | H8: ('S', 'E') | U8: FALSE
A9: 25_b | B9: =VLOOKUP(A9,PIPE!A:D,4,0) -> 297.08 | C9: 0 | E9: 109.53 | F9: 297.08 | G9: (27, 16) | H9: ('A', 'E') | U9: FALSE
A10: 28_a | B10: =VLOOKUP(A10,PIPE!A:D,4,0) -> 496.16 | C10: 0 | E10: 207.57 | F10: 496.16 | G10: (13, 16) | H10: ('E', 'E') | U10: FALSE
A11: 10_b | B11: =VLOOKUP(A11,PIPE!A:D,4,0) -> 141.73 | C11: 0 | E11: 132.71 | F11: 141.73 | G11: (22, 18) | H11: ('S', 'E') | U11: FALSE
A12: 70_a | B12: =VLOOKUP(A12,PIPE!A:D,4,0) -> 369.46 | C12: 0 | E12: 64.08 | F12: 369.46 | G12: (16, 19) | H12: ('E', 'S') | U12: FALSE
A13: 67_b | B13: =VLOOKUP(A13,PIPE!A:D,4,0) -> 110.44 | C13: 0 | E13: 85.34 | F13: 110.44 | G13: (26, 11) | H13: ('A', 'E') | U13: FALSE
A14: 34_b | B14: =VLOOKUP(A14,PIPE!A:D,4,0) -> 553.72 | C14: 0 | E14: 200.08 | F14: 553.72 | G14: (12, 11) | H14: ('E', 'E') | U14: FALSE
... A37: 41_a | B37: =VLOOKUP(A37,PIPE!A:D,4,0) -> 100.6 | C37: 0 | E37: 0 | F37: 100.6 | G37: (12, 20) | H37: ('E', 'S') | U37: FALSE
A38: 5_a | B38: =VLOOKUP(A38,PIPE!A:D,4,0) -> 80.23 | C38: 1 | D38: 30 | E38: 65.69 | F38: 80.23 | G38: (13, 23) | H38: ('E', 'S') | I38: 150 | J38: 113.38214 | K38: 142.06171 | L38: 113.38214 | M38: 45 | N38: 35.774081 | O38: 37.353685 | P38: 35.145913 | Q38: 0 | S38: 2035 | T38: 115.19613 | U38: FALSE | V38: 2 | W38: 0 | Z38: 0 | AA38: 0 | AB38: 0 | AC38: 63.92 | AD38: 67.67
A39: 7_b | B39: =VLOOKUP(A39,PIPE!A:D,4,0) -> 518.06 | C39: 0 | E39: 167.02 | F39: 518.06 | G39: (17, 6) | H39: ('E', 'K') | U39: FALSE
A40: 14_a | B40: =VLOOKUP(A40,PIPE!A:D,4,0) -> 222.05 | C40: 1 | D40: 26 | E40: 147.03 | F40: 222.05 | G40: (10, 21) | H40: ('E', 'S') | I40: 150 | J40: 78.24019 | K40: 141.68952 | L40: 78.24019 | M40: 45 | N40: 32.339456 | O40: 43.137131 | P40: 31.64011 | Q40: 1 | R40: 2045 | S40: 2045 | T40: 223.74704 | U40: TRUE | V40: 0.43 | W40: 63.927725 | X40: 50 | Y40: 10 | Z40: 0 | AA40: 0 | AB40: 0 | AC40: 40.155021 | AD40: 55.110648
A41: 16_a | B41: =VLOOKUP(A41,PIPE!A:D,4,0) -> 555.74 | C41: 0 | E41: 30.51 | F41: 555.74 | G41: (12, 27) | H41: ('E', 'A') | U41: FALSE
A42: 37_b | B42: =VLOOKUP(A42,PIPE!A:D,4,0) -> 347.61 | C42: 0 | E42: 86.53 | F42: 347.61 | G42: (24, 5) | H42: ('S', 'K') | U42: FALSE
A43: 47_a | B43: =VLOOKUP(A43,PIPE!A:D,4,0) -> 562.63 | C43: 0 | E43: 31.51 | F43: 562.63 | G43: (12, 26) | H43: ('E', 'A') | U43: FALSE
A44: 0_b | B44: =VLOOKUP(A44,PIPE!A:D,4,0) -> 423.46 | C44: 0 | E44: 121.13 | F44: 423.46 | G44: (5, 4) | H44: ('K', 'K') | U44: FALSE
A45: 0_a | B45: =VLOOKUP(A45,PIPE!A:D,4,0) -> 423.46 | C45: 0 | E45: 302.33 | F45: 423.46 | G45: (4, 5) | H45: ('K', 'K') | U45: FALSE
A46: 17_a | B46: =VLOOKUP(A46,PIPE!A:D,4,0) -> 336.49 | C46: 0 | E46: 295.43 | F46: 336.49 | G46: (11, 25) | H46: ('E', 'A') | U46: FALSE
A47: 26_a | B47: =VLOOKUP(A47,PIPE!A:D,4,0) -> 263.91 | C47: 0 | E47: 129.2 | F47: 263.91 | G47: (19, 23) | H47: ('S', 'S') | U47: FALSE
A48: 30_a | B48: =VLOOKUP(A48,PIPE!A:D,4,0) -> 243.08 | C48: 0 | E48: 44.01 | F48: 243.08 | G48: (13, 19) | H48: ('E', 'S') | U48: FALSE
A49: 3_b | B49: =VLOOKUP(A49,PIPE!A:D,4,0) -> 68.85 | C49: 1 | D49: 34 | E49: 57.79 | F49: 68.85 | G49: (17, 4) | H49: ('E', 'K') | I49: 150 | J49: 138.18312 | K49: 143.13227 | L49: 138.18312 | M49: 45 | N49: 39.013584 | O49: 38.693962 | P49: 38.535901 | Q49: 0 | S49: 2035 | T49: 107.77334 | U49: FALSE | V49: 2 | W49: 0 | Z49: 0 | AA49: 54.264 | AB49: 71.61 | AC49: 74.21 | AD49: 77.28
A50: 32_a | B50: =VLOOKUP(A50,PIPE!A:D,4,0) -> 345.18 | C50: 0 | E50: 303.66 | F50: 345.18 | G50: (5, 21) | H50: ('K', 'S') | U50: FALSE
A51: 49_b | B51: =VLOOKUP(A51,PIPE!A:D,4,0) -> 302.06 | C51: 0 | E51: 48.51 | F51: 302.06 | G51: (25, 17) | H51: ('A', 'E') | U51: FALSE
A52: 47_b | B52: =VLOOKUP(A52,PIPE!A:D,4,0) -> 562.63 | C52: 0 | E52: 530.62 | F52: 562.63 | G52: (26, 12) | H52: ('A', 'E') | U52: FALSE
A53: 31_b | B53: =VLOOKUP(A53,PIPE!A:D,4,0) -> 228.48 | C53: 0 | E53: 142.8 | F53: 228.48 | G53: (22, 15) | H53: ('S', 'E') | U53: FALSE
A54: 2_b | B54: =VLOOKUP(A54,PIPE!A:D,4,0) -> 448.83 | C54: 1 | D54: 26 | E54: 328.74 | F54: 448.83 | G54: (11, 4) | H54: ('E', 'K') | I54: 150 | J54: 76.394582 | K54: 158.73614 | L54: 76.394582 | M54: 45 | N54: 29.55172 | O54: 42.362227 | P54: 28.952224 | Q54: 1 | R54: 2045 | S54: 2045 | T54: 439.43621 | U54: TRUE | V54: 0.43 | W54: 125.5532 | X54: 50 | Y54: 10 | Z54: 0 | AA54: 0 | AB54: 0 | AC54: 45.329021 | AD54: 53.652628
A55: 4_b | B55: =VLOOKUP(A55,PIPE!A:D,4,0) -> 151.35 | C55: 1 | D55: 30 | E55: 51.62 | F55: 151.35 | G55: (14, 6) | H55: ('E', 'K') | I55: 150 | J55: 105.252 | K55: 195.26472 | L55: 105.252 | M55: 45 | N55: 35.051578 | O55: 34.118409 | P55: 33.907369 | Q55: 0 | S55: 2040 | T55: 161.43178 | U55: FALSE | V55: 2 | W55: 0 | Z55: 0 | AA55: 0 | AB55: 44.674 | AC55: 54.12 | AD55: 56.32
A56: 37_a | B56: =VLOOKUP(A56,PIPE!A:D,4,0) -> 347.61 | C56: 0 | E56: 261.08 | F56: 347.61 | G56: (5, 24) | H56: ('K', 'S') | U56: FALSE
A57: 64_a | B57: =VLOOKUP(A57,PIPE!A:D,4,0) -> 245.06 | C57: 0 | E57: 222.05 | F57: 245.06 | G57: (17, 24) | H57: ('E', 'S') | U57: FALSE
A58: 44_b | B58: =VLOOKUP(A58,PIPE!A:D,4,0) -> 348.87 | C58: 0 | E58: 258.27 | F58: 348.87 | G58: (23, 12) | H58: ('S', 'E') | U58: FALSE
A59: 40_b | B59: =VLOOKUP(A59,PIPE!A:D,4,0) -> 326.42 | C59: 0 | E59: 209.77 | F59: 326.42 | G59: (21, 20) | H59: ('S', 'S') | U59: FALSE
A60: 62_b | B60: =VLOOKUP(A60,PIPE!A:D,4,0) -> 147.41 | C60: 0 | E60: 61.67 | F60: 147.41 | G60: (22, 10) | H60: ('S', 'E') | U60: FALSE
A61: 36_a | B61: =VLOOKUP(A61,PIPE!A:D,4,0) -> 325.83 | C61: 0 | E61: 77.08 | F61: 325.83 | G61: (10, 20) | H61: ('E', 'S') | U61: FALSE
A62: 5_b | B62: =VLOOKUP(A62,PIPE!A:D,4,0) -> 80.23 | C62: 0 | E62: 14.54 | F62: 80.23 | G62: (23, 13) | H62: ('S', 'E') | U62: FALSE
...

Sheet PIPE
A1: Pipeline identifier | B1: Node connection | C1: Connection type | D1: Longitude (km)
A2: 0_a | B2: (4, 5) | C2: ('K', 'K') | D2: 423.46
A3: 0_b | B3: (5, 4) | C3: ('K', 'K') | D3: 423.46
A4: 1_a | B4: (19, 27) | C4: ('S', 'A') | D4: 491.3
A5: 1_b | B5: (27, 19) | C5: ('A', 'S') | D5: 491.3
A6: 2_a | B6: (4, 11) | C6: ('K', 'E') | D6: 448.83
A7: 2_b | B7: (11, 4) | C7: ('E', 'K') | D7: 448.83
A8: 3_a | B8: (4, 17) | C8: ('K', 'E') | D8: 68.85
A9: 3_b | B9: (17, 4) | C9: ('E', 'K') | D9: 68.85
A10: 4_a | B10: (6, 14) | C10: ('K', 'E') | D10: 151.35
A11: 4_b | B11: (14, 6) | C11: ('E', 'K') | D11: 151.35
A12: 5_a | B12: (13, 23) | C12: ('E', 'S') | D12: 80.23
A13: 5_b | B13: (23, 13) | C13: ('S', 'E') | D13: 80.23
... A109: 71_b | B109: (9, 8) | C109: ('E', 'E') | D109: 192.08

Sheet EUS - Sinks capacity evolution
A1: Sink node | B1: Initial capacity [Mt] | C1: 2030 capacity [Mt] | D1: 2035 capacity [Mt] | E1: 2040 capacity [Mt] | F1: 2045 capacity [Mt] | G1: 2050 capacity [Mt] | H1: Final capacity [Mt]
A2: 1 | B2: 1250 | C2: 1250 | D2: 1250 | E2: 1250 | F2: 1250 | G2: 1250 | H2: 1250
A3: 2 | B3: 3790 | C3: 3790 | D3: 3790 | E3: 3654.236 | F3: 3522.906 | G3: 3439.775 | H3: 3366.3576
A4: 3 | B4: 2100 | C4: 2100 | D4: 2100 | E4: 2100 | F4: 1995.36 | G4: 1887.97 | H4: 1777.12
A5: 19 | B5: 6655.37 | C5: 6655.37 | D5: 6655.37 | E5: 6655.37 | F5: 6655.37 | G5: 6655.37 | H5: 6655.37
A6: 20 | B6: 4571.37 | C6: 4571.37 | D6: 4571.37 | E6: 4571.37 | F6: 4571.37 | G6: 4571.37 | H6: 4571.37
A7: 21 | B7: 1372.72 | C7: 1372.72 | D7: 1323.17 | E7: 1272.44 | F7: 1264.854 | G7: 1224.699 | H7: 1188.2683
A8: 22 | B8: 2171.48 | C8: 2171.48 | D8: 2151.842 | E8: 2151.842 | F8: 2124.232 | G8: 2095.722 | H8: 2041.678
A9: 23 | B9: 4632.05 | C9: 4632.05 | D9: 4632.05 | E9: 4632.05 | F9: 4632.05 | G9: 4568.13 | H9: 4500.46
A10: 24 | B10: 1319.75 | C10: 1319.75 | D10: 1319.75 | E10: 1319.75 | F10: 1319.75 | G10: 1319.75 | H10: 1319.75

Sheet EUS - Utilization evolution
A1: Utilization node | B1: Utilization capacity [Mt] | C1: 2030 utilization [Mt] | D1: 2035 utilization [Mt] | E1: 2040 utilization [Mt] | F1: 2045 utilization [Mt] | G1: 2050 utilization [Mt]
A2: 4 | B2: 150 | C2: 0 | D2: 54.264 | E2: 71.61 | F2: 119.53902 | G2: 130.93263
A3: 5 | B3: 75 | C3: 0 | D3: 0 | E3: 0 | F3: 26.413979 | G3: 75
A4: 6 | B4: 75 | C4: 0 | D4: 0 | E4: 44.674 | F4: 54.12 | G4: 75

Sheet EUS - Cost breakdown
A1: Concept | B1: 2030 | C1: 2035 | D1: 2040 | E1: 2045 | F1: 2050 | G1: Total
A2: Capture cost | B2: 5288.0388 | C2: 13947.111 | D2: 17012.929 | E2: 17416.629 | F2: 15726.985 | G2: 69391.693
A3: Injection cost | B3: 453.1814 | C3: 925.01024 | D3: 1022.2958 | E3: 920.8521 | F3: 739.60992 | G3: 4060.9495
A4: CAPEX onshore pipe | B4: 677.888 | C4: 439.26772 | D4: 570.98279 | E4: 706.60298 | F4: 545.57377 | G4: 2940.3153
A5: CAPEX onshore pipe (insulation only) | B5: 193.68229 | C5: 0 | D5: 0 | E5: 189.48093 | F5: 57.531404 | G5: 440.69462
A6: CAPEX offshore pipe | B6: 0 | C6: 98.422962 | D6: 66.686421 | E6: 0 | F6: 0 | G6: 165.10938
A7: CAPEX initial boosting stations | B7: 4983.8968 | C7: 9647.4559 | D7: 3694.8522 | E7: 3954.129 | F7: 1398.8621 | G7: 23679.196
A8: CAPEX additional boosting stations | B8: 0 | C8: 0 | D8: 247.333 | E8: 175.4723 | F8: 249.93657 | G8: 672.74188
A9: OPEX onshore pipe | B9: 88.125663 | C9: 123.90442 | D9: 168.14644 | E9: 219.31186 | F9: 237.16492 | G9: 836.65331
A10: OPEX onshore pipe (insulation only) | B10: 25.178761 | C10: 19.085565 | D10: 14.466645 | E10: 35.597508 | F10: 34.462767 | G10: 128.79125
A11: OPEX offshore pipe | B11: 0 | C11: 12.795014 | D11: 18.367903 | E11: 13.9229 | F11: 10.553524 | G11: 55.639341
A12: OPEX initial boosting stations | B12: 134.62097 | C12: 362.6964 | D12: 374.535 | E12: 390.5473 | F12: 333.82173 | G12: 1596.2214
A13: OPEX additional boosting stations | B13: 0 | C13: 0 | D13: 6.3569644 | E13: 9.3456572 | F13: 13.485478 | G13: 29.188099
... A19: TOTAL | B19: 57951.884 | C19: 48657.246 | D19: 32404.287 | E19: 24635.168 | F19: 13192.677 | G19: 176841.26

Sheet HUS - Pipes
A1: Pipe ID | B1: Installed | C1: Diameter [inch] | D1: Distance until highest point [km] | E1: Longitude [km] | F1: Node connections | G1: Node types | H1: Initial pressure [bar] | I1: Pressure at highest point [bar] | J1: Final pressure [bar] | K1: Lowest pressure [bar] | L1: Initial temperature [°C] | M1: Temperature at critical pressure point [°C] | N1: Final temperature [°C] | O1: Lowest temperature [°C] | P1: Number of boosters | Q1: Booster installation year | R1: Installation Year | S1: Present Value Cost [M€] | T1: Insulated | U1: U-value [W/m^2/K] | V1: Insulation cost [M€] | W1: Booster delta pressure [bar] | X1: Booster delta temperature [°C] | Y1: Flow in 2030 | Z1: Flow in 2035 | AA1: Flow in 2040 | AB1: Flow in 2045 | AC1: Flow in 2050
A2: 25_a | B2: 1 | C2: 38 | D2: 186.05 | E2: 297.08 | F2: (16, 27) | G2: ('E', 'A') | H2: 150 | I2: 87.381501 | J2: 229.19293 | K2: 87.381501 | L2: 45 | M2: 27.095937 | N2: 40.276309 | O2: 27.123708 | P2: 1 | Q2: 2040 | R2: 2040 | S2: 409.55101 | T2: FALSE | U2: 2 | V2: 0 | W2: 50 | X2: 10 | Y2: 0 | Z2: 0 | AA2: 104.64 | AB2: 96.357372 | AC2: 110.85
A3: 60_a | B3: 0 | D3: 84.57 | E3: 127.1 | F3: (6, 21) | G3: ('K', 'S') | T3: FALSE
A4: 1_a | B4: 0 | D4: 350.21 | E4: 491.3 | F4: (19, 27) | G4: ('S', 'A') | T4: FALSE
A5: 9_a | B5: 0 | D5: 482.28 | E5: 484.78 | F5: (15, 23) | G5: ('E', 'S') | T5: FALSE
A6: 57_b | B6: 0 | D6: 85.12 | E6: 166.23 | F6: (28, 21) | G6: ('A', 'S') | T6: FALSE
A7: 56_b | B7: 0 | D7: 222.78 | E7: 263.83 | F7: (18, 15) | G7: ('E', 'E') | T7: FALSE
A8: 9_b | B8: 0 | D8: 2.5 | E8: 484.78 | F8: (23, 15) | G8: ('S', 'E') | T8: FALSE
A9: 25_b | B9: 0 | D9: 109.53 | E9: 297.08 | F9: (27, 16) | G9: ('A', 'E') | T9: FALSE
A10: 28_a | B10: 0 | D10: 207.57 | E10: 496.16 | F10: (13, 16) | G10: ('E', 'E') | T10: FALSE
A11: 10_b | B11: 0 | D11: 132.71 | E11: 141.73 | F11: (22, 18) | G11: ('S', 'E') | T11: FALSE
A12: 70_a | B12: 0 | D12: 64.08 | E12: 369.46 | F12: (16, 19) | G12: ('E', 'S') | T12: FALSE
A13: 67_b | B13: 0 | D13: 85.34 | E13: 110.44 | F13: (26, 11) | G13: ('A', 'E') | T13: FALSE
A14: 34_b | B14: 0 | D14: 200.08 | E14: 553.72 | F14: (12, 11) | G14: ('E', 'E') | T14: FALSE
... A37: 41_a | B37: 0 | D37: 0 | E37: 100.6 | F37: (12, 20) | G37: ('E', 'S') | T37: FALSE
A38: 5_a | B38: 1 | C38: 30 | D38: 65.69 | E38: 80.23 | F38: (13, 23) | G38: ('E', 'S') | H38: 150 | I38: 113.38214 | J38: 142.06171 | K38: 113.38214 | L38: 45 | M38: 35.774081 | N38: 37.353685 | O38: 35.145913 | P38: 0 | R38: 2035 | S38: 115.19613 | T38: FALSE | U38: 2 | V38: 0 | Y38: 0 | Z38: 0 | AA38: 0 | AB38: 63.92 | AC38: 67.67
A39: 7_b | B39: 0 | D39: 167.02 | E39: 518.06 | F39: (17, 6) | G39: ('E', 'K') | T39: FALSE
A40: 14_a | B40: 1 | C40: 26 | D40: 147.03 | E40: 222.05 | F40: (10, 21) | G40: ('E', 'S') | H40: 150 | I40: 78.24019 | J40: 141.68952 | K40: 78.24019 | L40: 45 | M40: 32.339456 | N40: 43.137131 | O40: 31.64011 | P40: 1 | Q40: 2045 | R40: 2045 | S40: 223.74704 | T40: TRUE | U40: 0.43 | V40: 63.927725 | W40: 50 | X40: 10 | Y40: 0 | Z40: 0 | AA40: 0 | AB40: 55.110648 | AC40: 55.110648
A41: 16_a | B41: 0 | D41: 30.51 | E41: 555.74 | F41: (12, 27) | G41: ('E', 'A') | T41: FALSE
A42: 37_b | B42: 0 | D42: 86.53 | E42: 347.61 | F42: (24, 5) | G42: ('S', 'K') | T42: FALSE
A43: 47_a | B43: 0 | D43: 31.51 | E43: 562.63 | F43: (12, 26) | G43: ('E', 'A') | T43: FALSE
A44: 0_b | B44: 0 | D44: 121.13 | E44: 423.46 | F44: (5, 4) | G44: ('K', 'K') | T44: FALSE
A45: 0_a | B45: 0 | D45: 302.33 | E45: 423.46 | F45: (4, 5) | G45: ('K', 'K') | T45: FALSE
A46: 17_a | B46: 0 | D46: 295.43 | E46: 336.49 | F46: (11, 25) | G46: ('E', 'A') | T46: FALSE
A47: 26_a | B47: 0 | D47: 129.2 | E47: 263.91 | F47: (19, 23) | G47: ('S', 'S') | T47: FALSE
A48: 30_a | B48: 0 | D48: 44.01 | E48: 243.08 | F48: (13, 19) | G48: ('E', 'S') | T48: FALSE
A49: 3_b | B49: 1 | C49: 34 | D49: 57.79 | E49: 68.85 | F49: (17, 4) | G49: ('E', 'K') | H49: 150 | I49: 138.18312 | J49: 143.13227 | K49: 138.18312 | L49: 45 | M49: 39.013584 | N49: 38.693962 | O49: 38.535901 | P49: 0 | R49: 2035 | S49: 107.77334 | T49: FALSE | U49: 2 | V49: 0 | Y49: 0 | Z49: 65.417173 | AA49: 71.61 | AB49: 74.21 | AC49: 77.28
A50: 32_a | B50: 0 | D50: 303.66 | E50: 345.18 | F50: (5, 21) | G50: ('K', 'S') | T50: FALSE
A51: 49_b | B51: 0 | D51: 48.51 | E51: 302.06 | F51: (25, 17) | G51: ('A', 'E') | T51: FALSE
A52: 47_b | B52: 0 | D52: 530.62 | E52: 562.63 | F52: (26, 12) | G52: ('A', 'E') | T52: FALSE
A53: 31_b | B53: 0 | D53: 142.8 | E53: 228.48 | F53: (22, 15) | G53: ('S', 'E') | T53: FALSE
A54: 2_b | B54: 1 | C54: 42 | D54: 328.74 | E54: 448.83 | F54: (11, 4) | G54: ('E', 'K') | H54: 150 | I54: 89.87825 | J54: 175.79455 | K54: 89.87825 | L54: 45 | M54: 33.375196 | N54: 47.794334 | O54: 33.373565 | P54: 1 | Q54: 2040 | R54: 2040 | S54: 936.4846 | T54: TRUE | U54: 0.43 | V54: 267.56703 | W54: 50 | X54: 10 | Y54: 0 | Z54: 0 | AA54: 86.809173 | AB54: 90.254872 | AC54: 119.78848
A55: 4_b | B55: 1 | C55: 14 | D55: 51.62 | E55: 151.35 | F55: (14, 6) | G55: ('E', 'K') | H55: 150 | I55: 100.15985 | J55: 173.93481 | K55: 100.15985 | L55: 45 | M55: 36.155662 | N55: 40.953324 | O55: 36.810053 | P55: 0 | R55: 2035 | S55: 139.14035 | T55: TRUE | U55: 0.43 | V55: 39.754385 | Y55: 0 | Z55: 15.978827 | AA55: 15.978827 | AB55: 15.978827 | AC55: 1.2093518
A56: 37_a | B56: 0 | D56: 261.08 | E56: 347.61 | F56: (5, 24) | G56: ('K', 'S') | T56: FALSE
A57: 64_a | B57: 0 | D57: 222.05 | E57: 245.06 | F57: (17, 24) | G57: ('E', 'S') | T57: FALSE
A58: 44_b | B58: 0 | D58: 258.27 | E58: 348.87 | F58: (23, 12) | G58: ('S', 'E') | T58: FALSE
A59: 40_b | B59: 0 | D59: 209.77 | E59: 326.42 | F59: (21, 20) | G59: ('S', 'S') | T59: FALSE
A60: 62_b | B60: 0 | D60: 61.67 | E60: 147.41 | F60: (22, 10) | G60: ('S', 'E') | T60: FALSE
A61: 36_a | B61: 0 | D61: 77.08 | E61: 325.83 | F61: (10, 20) | G61: ('E', 'S') | T61: FALSE
A62: 5_b | B62: 0 | D62: 14.54 | E62: 80.23 | F62: (23, 13) | G62: ('S', 'E') | T62: FALSE
...

Sheet HUS - Sinks capacity evolution
A1: Sink node | B1: Initial capacity [Mt] | C1: 2030 capacity [Mt] | D1: 2035 capacity [Mt] | E1: 2040 capacity [Mt] | F1: 2045 capacity [Mt] | G1: 2050 capacity [Mt] | H1: Final capacity [Mt]
A2: 1 | B2: 1250 | C2: 1250 | D2: 1250 | E2: 1250 | F2: 1250 | G2: 1250 | H2: 1250
A3: 2 | B3: 3790 | C3: 3790 | D3: 3790 | E3: 3654.18 | F3: 3609.6592 | G3: 3571.454 | H3: 3564.1725
A4: 3 | B4: 2100 | C4: 2100 | D4: 2100 | E4: 2100 | F4: 1995.36 | G4: 1899.0026 | H4: 1788.1526
A5: 19 | B5: 6655.37 | C5: 6655.37 | D5: 6655.37 | E5: 6655.37 | F5: 6655.37 | G5: 6655.37 | H5: 6655.37
A6: 20 | B6: 4571.37 | C6: 4571.37 | D6: 4571.37 | E6: 4571.37 | F6: 4571.37 | G6: 4571.37 | H6: 4571.37
A7: 21 | B7: 1372.72 | C7: 1372.72 | D7: 1323.17 | E7: 1298.564 | F7: 1262.2828 | G7: 1262.2828 | H7: 1262.2828
A8: 22 | B8: 2171.48 | C8: 2171.48 | D8: 2151.842 | E8: 2151.842 | F8: 2124.232 | G8: 2095.722 | H8: 2079.178
A9: 23 | B9: 4632.05 | C9: 4632.05 | D9: 4632.05 | E9: 4632.05 | F9: 4632.05 | G9: 4568.13 | H9: 4500.46
A10: 24 | B10: 1319.75 | C10: 1319.75 | D10: 1319.75 | E10: 1319.75 | F10: 1319.75 | G10: 1319.75 | H10: 1319.75

Sheet HUS - Utilization evolution
A1: Utilization node | B1: Utilization capacity [Mt] | C1: 2030 utilization [Mt] | D1: 2035 utilization [Mt] | E1: 2040 utilization [Mt] | F1: 2045 utilization [Mt] | G1: 2050 utilization [Mt]
A2: 4 | B2: 225 | C2: 0 | D2: 65.417173 | E2: 158.41917 | F2: 164.46487 | G2: 197.06848
A3: 5 | B3: 112.5 | C3: 0 | D3: 0 | E3: 0 | F3: 26.413979 | G3: 112.5
A4: 6 | B4: 112.5 | C4: 0 | D4: 15.978827 | E4: 15.978827 | F4: 109.23065 | G4: 111.43065

Sheet HUS - Cost breakdown
A1: Concept | B1: 2030 | C1: 2035 | D1: 2040 | E1: 2045 | F1: 2050 | G1: Total
A2: Capture cost | B2: 5288.0388 | C2: 14008.748 | D2: 17012.929 | E2: 17547.226 | F2: 15726.985 | G2: 69583.927
A3: Injection cost | B3: 453.1814 | C3: 795.71296 | D3: 803.20604 | E3: 646.92863 | F3: 437.06628 | G3: 3136.0953
A4: CAPEX onshore pipe | B4: 677.888 | C4: 578.40807 | D4: 1387.6676 | E4: 406.61234 | F4: 476.97046 | G4: 3527.5465
A5: CAPEX onshore pipe (insulation only) | B5: 193.68229 | C5: 39.754385 | D5: 267.56703 | E5: 63.927725 | F5: 57.531404 | G5: 622.46283
A6: CAPEX offshore pipe | B6: 0 | C6: 98.422962 | D6: 66.686421 | E6: 0 | F6: 0 | G6: 165.10938
A7: CAPEX initial boosting stations | B7: 4983.8968 | C7: 9647.4559 | D7: 3694.8522 | E7: 3954.129 | F7: 1398.8621 | G7: 23679.196
A8: CAPEX additional boosting stations | B8: 0 | C8: 0 | D8: 549.47664 | E8: 87.736152 | F8: 249.93657 | G8: 887.14937
A9: OPEX onshore pipe | B9: 88.125663 | C9: 141.99271 | D9: 288.02749 | E9: 271.18378 | F9: 267.56553 | G9: 1056.8952
A10: OPEX onshore pipe (insulation only) | B10: 25.178761 | C10: 24.253647 | D10: 53.167988 | E10: 48.611528 | F10: 44.327492 | G10: 195.53942
A11: OPEX offshore pipe | B11: 0 | C11: 12.795014 | D11: 18.367903 | E11: 13.9229 | F11: 10.553524 | G11: 55.639341
A12: OPEX initial boosting stations | B12: 134.62097 | C12: 362.6964 | D12: 374.535 | E12: 390.5473 | F12: 333.82173 | G12: 1596.2214
A13: OPEX additional boosting stations | B13: 0 | C13: 0 | D13: 14.122674 | E13: 12.982308 | F13: 16.23514 | G13: 43.340122
... A19: TOTAL | B19: 57951.884 | C19: 46530.92 | D19: 29990.086 | E19: 19340.339 | F19: 8056.589 | G19: 161869.82

Sheet Network length per scenario
A1: Scenario | B1: 2030 | C1: 2035 | D1: 2040 | E1: 2045 | F1: 2050
A2: LUS | B2: 321.2 | C2: 688.95 | D2: 1089.57 | E2: 1380.47 | F2: 1952.92
A3: EUS | B3: 321.2 | C3: 606.45 | D3: 1080.3 | E3: 1829.3 | F3: 2574.13
A4: HUS | B4: 321.2 | C4: 757.8 | D4: 1718.79 | E4: 2146.06 | F4: 2763.79
