Workbook

Sheet LUS - Pipes
A1: Pipe ID | B1: Installed | C1: Diameter [inch] | D1: Distance until highest point [km] | E1: Longitude [km] | F1: Node connections | G1: Node types | H1: Initial pressure [bar] | I1: Pressure at highest point [bar] | J1: Final pressure [bar] | K1: Lowest pressure [bar] | L1: Initial temperature [°C] | M1: Temperature at critical pressure point [°C] | N1: Final temperature [°C] | O1: Lowest temperature [°C] | P1: Number of boosters | Q1: Booster installation year | R1: Installation Year | S1: Present Value Cost [M€] | T1: Insulated | U1: U-value [W/m^2/K] | V1: Insulation cost [M€] | W1: Booster delta pressure [bar] | X1: Booster delta temperature [°C] | Y1: Flow in 2030 | Z1: Flow in 2035 | AA1: Flow in 2040 | AB1: Flow in 2045 | AC1: Flow in 2050
A2: 17_a | B2: 0 | D2: 295.43 | E2: 336.49 | F2: (11, 25) | G2: ('E', 'A') | T2: FALSE
A3: 4_a | B3: 0 | D3: 99.73 | E3: 151.35 | F3: (6, 14) | G3: ('K', 'E') | T3: FALSE
A4: 49_a | B4: 0 | D4: 165.53 | E4: 302.06 | F4: (17, 25) | G4: ('E', 'A') | T4: FALSE
A5: 36_a | B5: 0 | D5: 77.08 | E5: 325.83 | F5: (10, 20) | G5: ('E', 'S') | T5: FALSE
A6: 63_a | B6: 0 | D6: 313.27 | E6: 447.89 | F6: (11, 17) | G6: ('E', 'E') | T6: FALSE
A7: 40_b | B7: 0 | D7: 209.77 | E7: 326.42 | F7: (21, 20) | G7: ('S', 'S') | T7: FALSE
A8: 59_a | B8: 0 | D8: 201.52 | E8: 356.04 | F8: (18, 20) | G8: ('E', 'S') | T8: FALSE
A9: 25_a | B9: 1 | C9: 38 | D9: 186.05 | E9: 297.08 | F9: (16, 27) | G9: ('E', 'A') | H9: 150 | I9: 83.176683 | J9: 238.75987 | K9: 83.176683 | L9: 25 | M9: 15.521725 | N9: 27.357529 | O9: 15.4939 | P9: 1 | Q9: 2045 | R9: 2045 | S9: 310.44075 | T9: FALSE | U9: 2 | V9: 0 | W9: 50 | X9: 10 | Y9: 0 | Z9: 0 | AA9: 0 | AB9: 107.39 | AC9: 110.85
A10: 37_b | B10: 0 | D10: 86.53 | E10: 347.61 | F10: (24, 5) | G10: ('S', 'K') | T10: FALSE
A11: 56_a | B11: 0 | D11: 41.05 | E11: 263.83 | F11: (15, 18) | G11: ('E', 'E') | T11: FALSE
A12: 31_a | B12: 1 | C12: 30 | D12: 85.68 | E12: 228.48 | F12: (15, 22) | G12: ('E', 'S') | H12: 150 | I12: 87.35104 | J12: 157.66753 | K12: 87.35104 | L12: 25 | M12: 18.302202 | N12: 25.322261 | O12: 15.341525 | P12: 1 | Q12: 2040 | R12: 2040 | S12: 250.32444 | T12: FALSE | U12: 2 | V12: 0 | W12: 50 | X12: 10 | Y12: 0 | Z12: 0 | AA12: 66.89 | AB12: 63.751372 | AC12: 73.04
A13: 58_a | B13: 0 | D13: 164.64 | E13: 189.66 | F13: (4, 24) | G13: ('K', 'S') | T13: FALSE
A14: 31_b | B14: 0 | D14: 142.8 | E14: 228.48 | F14: (22, 15) | G14: ('S', 'E') | T14: FALSE
A15: 23_a | B15: 0 | D15: 38.1 | E15: 179.47 | F15: (14, 21) | G15: ('E', 'S') | T15: FALSE
A16: 44_b | B16: 0 | D16: 258.27 | E16: 348.87 | F16: (23, 12) | G16: ('S', 'E') | T16: FALSE
A17: 43_a | B17: 0 | D17: 148.58 | E17: 370.19 | F17: (14, 17) | G17: ('E', 'E') | T17: FALSE
A18: 29_b | B18: 1 | C18: 18 | D18: 0 | E18: 78.12 | F18: (12, 5) | G18: ('E', 'K') | H18: 150 | I18: 150 | J18: 182.827 | K18: 150 | L18: 25 | M18: 25 | N18: 18.083504 | O18: 18.10041 | P18: 0 | R18: 2030 | S18: 99.69535 | T18: FALSE | U18: 2 | V18: 0 | Y18: 14.468 | Z18: 19.282 | AA18: 25.8 | AB18: 26.413979 | AC18: 26.413979
A19: 13_b | B19: 1 | C19: 34 | D19: 183.25 | E19: 343.97 | F19: (22, 20) | G19: ('S', 'S') | H19: 178.00921 | I19: 72.949938 | J19: 195.23118 | K19: 72.949938 | L19: 25.086203 | M19: 12.702641 | N19: 22.227783 | O19: 12.206166 | P19: 1 | Q19: 2050 | R19: 2050 | S19: 244.00848 | T19: FALSE | U19: 2 | V19: 0 | W19: 50 | X19: 10 | Y19: 0 | Z19: 0 | AA19: 0 | AB19: 0 | AC19: 0
A20: 43_b | B20: 0 | D20: 221.62 | E20: 370.19 | F20: (17, 14) | G20: ('E', 'E') | T20: FALSE
A21: 67_b | B21: 0 | D21: 85.34 | E21: 110.44 | F21: (26, 11) | G21: ('A', 'E') | T21: FALSE
A22: 51_a | B22: 0 | D22: 290.25 | E22: 463.4 | F22: (4, 12) | G22: ('K', 'E') | T22: FALSE
A23: 51_b | B23: 0 | D23: 173.15 | E23: 463.4 | F23: (12, 4) | G23: ('E', 'K') | T23: FALSE
A24: 3_b | B24: 1 | C24: 34 | D24: 57.79 | E24: 68.85 | F24: (17, 4) | G24: ('E', 'K') | H24: 150 | I24: 137.47836 | J24: 143.33677 | K24: 137.47836 | L24: 25 | M24: 21.998053 | N24: 21.839455 | O24: 21.759017 | P24: 0 | R24: 2035 | S24: 107.77334 | T24: FALSE | U24: 2 | V24: 0 | Y24: 0 | Z24: 27.132 | AA24: 60.486 | AB24: 74.21 | AC24: 75
A25: 14_a | B25: 1 | C25: 26 | D25: 147.03 | E25: 222.05 | F25: (10, 21) | G25: ('E', 'S') | H25: 150 | I25: 68.230718 | J25: 136.22208 | K25: 68.230718 | L25: 25 | M25: 14.398163 | N25: 23.788198 | O25: 13.25316 | P25: 1 | Q25: 2040 | R25: 2040 | S25: 210.84234 | T25: FALSE | U25: 2 | V25: 0 | W25: 50 | X25: 10 | Y25: 0 | Z25: 0 | AA25: 44.74 | AB25: 55.110648 | AC25: 55.110648
A26: 37_a | B26: 0 | D26: 261.08 | E26: 347.61 | F26: (5, 24) | G26: ('K', 'S') | T26: FALSE
A27: 3_a | B27: 0 | D27: 11.06 | E27: 68.85 | F27: (4, 17) | G27: ('K', 'E') | T27: FALSE
A28: 58_b | B28: 0 | D28: 25.02 | E28: 189.66 | F28: (24, 4) | G28: ('S', 'K') | T28: FALSE
A29: 28_b | B29: 0 | D29: 288.59 | E29: 496.16 | F29: (16, 13) | G29: ('E', 'E') | T29: FALSE
A30: 67_a | B30: 1 | C30: 42 | D30: 12.05 | E30: 110.44 | F30: (11, 26) | G30: ('E', 'A') | H30: 150 | I30: 104.45679 | J30: 153.46191 | K30: 104.45679 | L30: 25 | M30: 22.20149 | N30: 22.189588 | O30: 22.206751 | P30: 0 | R30: 2035 | S30: 216.29825 | T30: FALSE | U30: 2 | V30: 0 | Y30: 0 | Z30: 135.82 | AA30: 131.33 | AB30: 128.46 | AC30: 127.07
A31: 44_a | B31: 0 | D31: 90.6 | E31: 348.87 | F31: (12, 23) | G31: ('E', 'S') | T31: FALSE
A32: 34_b | B32: 0 | D32: 200.08 | E32: 553.72 | F32: (12, 11) | G32: ('E', 'E') | T32: FALSE
A33: 32_a | B33: 0 | D33: 303.66 | E33: 345.18 | F33: (5, 21) | G33: ('K', 'S') | T33: FALSE
A34: 64_a | B34: 0 | D34: 222.05 | E34: 245.06 | F34: (17, 24) | G34: ('E', 'S') | T34: FALSE
A35: 61_a | B35: 0 | D35: 229.52 | E35: 233.52 | F35: (18, 23) | G35: ('E', 'S') | T35: FALSE
A36: 62_b | B36: 0 | D36: 61.67 | E36: 147.41 | F36: (22, 10) | G36: ('S', 'E') | T36: FALSE
A37: 4_b | B37: 1 | C37: 38 | D37: 51.62 | E37: 151.35 | F37: (14, 6) | G37: ('E', 'K') | H37: 150 | I37: 100.14645 | J37: 205.93858 | K37: 100.14645 | L37: 25 | M37: 20.372963 | N37: 21.169234 | O37: 20.653032 | P37: 0 | R37: 2050 | S37: 117.48797 | T37: FALSE | U37: 2 | V37: 0 | Y37: 0 | Z37: 0 | AA37: 0 | AB37: 0 | AC37: 56.32
A38: 16_a | B38: 0 | D38: 30.51 | E38: 555.74 | F38: (12, 27) | G38: ('E', 'A') | T38: FALSE
A39: 5_b | B39: 0 | D39: 14.54 | E39: 80.23 | F39: (23, 13) | G39: ('S', 'E') | T39: FALSE
A40: 54_a | B40: 1 | C40: 18 | D40: 37.23 | E40: 45.28 | F40: (5, 20) | G40: ('K', 'S') | H40: 182.827 | I40: 165.79097 | J40: 166.05856 | K40: 165.79097 | L40: 18.083504 | M40: 16.497934 | N40: 16.317469 | O40: 16.359963 | P40: 0 | R40: 2030 | S40: 81.477722 | T40: TRUE | U40: 0.43 | V40: 30.554146 | Y40: 14.468 | Z40: 19.282 | AA40: 25.8 | AB40: 0.58747932 | AC40: 0
...

Sheet LUS - Sinks capacity evolution
A1: Sink node | B1: Initial capacity [Mt] | C1: 2030 capacity [Mt] | D1: 2035 capacity [Mt] | E1: 2040 capacity [Mt] | F1: 2045 capacity [Mt] | G1: 2050 capacity [Mt] | H1: Final capacity [Mt]
A2: 1 | B2: 1250 | C2: 1250 | D2: 1250 | E2: 1250 | F2: 1250 | G2: 1250 | H2: 1250
A3: 2 | B3: 3790 | C3: 3790 | D3: 3790 | E3: 3654.18 | F3: 3522.85 | G3: 3394.39 | H3: 3267.32
A4: 3 | B4: 2100 | C4: 2100 | D4: 2100 | E4: 2100 | F4: 2100 | G4: 1992.61 | H4: 1881.76
A5: 19 | B5: 6655.37 | C5: 6655.37 | D5: 6655.37 | E5: 6655.37 | F5: 6655.37 | G5: 6655.37 | H5: 6655.37
A6: 20 | B6: 4571.37 | C6: 4571.37 | D6: 4556.902 | E6: 4537.62 | F6: 4511.82 | G6: 4511.2325 | H6: 4510.9047
A7: 21 | B7: 1372.72 | C7: 1372.72 | D7: 1372.72 | E7: 1372.72 | F7: 1327.98 | G7: 1272.8694 | H7: 1198.9387
A8: 22 | B8: 2171.48 | C8: 2171.48 | D8: 2171.48 | E8: 2171.48 | F8: 2104.59 | G8: 2040.8386 | H8: 1938.2086
A9: 23 | B9: 4632.05 | C9: 4632.05 | D9: 4577.33 | E9: 4519.87 | F9: 4459.35 | G9: 4395.43 | H9: 4327.76
A10: 24 | B10: 1319.75 | C10: 1319.75 | D10: 1319.75 | E10: 1319.75 | F10: 1319.75 | G10: 1319.75 | H10: 1319.75

Sheet LUS - Utilization evolution
A1: Utilization node | B1: Utilization capacity [Mt] | C1: 2030 utilization [Mt] | D1: 2035 utilization [Mt] | E1: 2040 utilization [Mt] | F1: 2045 utilization [Mt] | G1: 2050 utilization [Mt]
A2: 4 | B2: 75 | C2: 0 | D2: 27.132 | E2: 60.486 | F2: 74.21 | G2: 75
A3: 5 | B3: 37.5 | C3: 0 | D3: 0 | E3: 0 | F3: 25.8265 | G3: 27.872148
A4: 6 | B4: 37.5 | C4: 0 | D4: 0 | E4: 0 | F4: 0 | G4: 37.5

Sheet LUS - Cost breakdown
A1: Concept | B1: 2030 | C1: 2035 | D1: 2040 | E1: 2045 | F1: 2050 | G1: Total
A2: Capture cost | B2: 5288.0388 | C2: 13885.473 | D2: 17114.625 | E2: 17286.032 | F2: 15714.522 | G2: 69288.691
A3: Injection cost | B3: 453.1814 | C3: 1054.3075 | D3: 1241.3856 | E3: 1194.7756 | F3: 1042.1536 | G3: 4985.8037
A4: CAPEX onshore pipe | B4: 333.14629 | C4: 324.07159 | D4: 461.16678 | E4: 394.22726 | F4: 456.90984 | G4: 1969.5218
A5: CAPEX onshore pipe (insulation only) | B5: 30.554146 | C5: 0 | D5: 0 | E5: 0 | F5: 5.5768456 | G5: 36.130991
A6: CAPEX offshore pipe | B6: 0 | C6: 98.422962 | D6: 0 | E6: 50.548483 | F6: 0 | G6: 148.97145
A7: CAPEX initial boosting stations | B7: 5561.7063 | C7: 9647.4559 | D7: 4455.4884 | E7: 2800.7361 | F7: 1645.3483 | G7: 24110.735
A8: CAPEX additional boosting stations | B8: 0 | C8: 0 | D8: 269.94239 | E8: 250.22974 | F8: 152.71715 | G8: 672.88928
A9: OPEX onshore pipe | B9: 43.309138 | C9: 74.957841 | D9: 116.76958 | E9: 139.76126 | F9: 165.33782 | G9: 540.13563
A10: OPEX onshore pipe (insulation only) | B10: 3.9720485 | C10: 3.010823 | D10: 2.282275 | E10: 1.7298952 | F10: 2.0363469 | G10: 13.031389
A11: OPEX offshore pipe | B11: 0 | C11: 12.795014 | D11: 9.6986662 | E11: 13.9229 | F11: 10.553524 | G11: 46.970104
A12: OPEX initial boosting stations | B12: 150.22829 | C12: 374.52888 | D12: 404.037 | E12: 381.76996 | F12: 333.82173 | G12: 1644.3859
A13: OPEX additional boosting stations | B13: 0 | C13: 0 | D13: 6.9380719 | E13: 11.712154 | F13: 12.777844 | G13: 31.42807
... A19: TOTAL | B19: 58155.742 | C19: 50788.49 | D19: 36521.376 | E19: 28204.247 | F19: 18339.501 | G19: 192009.36

Sheet EUS - Pipes
A1: Pipe ID | B1: Length [km] | C1: Installed | D1: Diameter [inch] | E1: Distance until highest point [km] | F1: Longitude [km] | G1: Node connections | H1: Node types | I1: Initial pressure [bar] | J1: Pressure at highest point [bar] | K1: Final pressure [bar] | L1: Lowest pressure [bar] | M1: Initial temperature [°C] | N1: Temperature at critical pressure point [°C] | O1: Final temperature [°C] | P1: Lowest temperature [°C] | Q1: Number of boosters | R1: Booster installation year | S1: Installation Year | T1: Present Value Cost [M€] | U1: Insulated | V1: U-value [W/m^2/K] | W1: Insulation cost [M€] | X1: Booster delta pressure [bar] | Y1: Booster delta temperature [°C] | Z1: Flow in 2030 | AA1: Flow in 2035 | AB1: Flow in 2040 | AC1: Flow in 2045 | AD1: Flow in 2050
A2: 17_a | B2: =VLOOKUP(A2,PIPE!A:D,4,0) -> 336.49 | C2: 0 | E2: 295.43 | F2: 336.49 | G2: (11, 25) | H2: ('E', 'A') | U2: FALSE
A3: 4_a | B3: =VLOOKUP(A3,PIPE!A:D,4,0) -> 151.35 | C3: 0 | E3: 99.73 | F3: 151.35 | G3: (6, 14) | H3: ('K', 'E') | U3: FALSE
A4: 49_a | B4: =VLOOKUP(A4,PIPE!A:D,4,0) -> 302.06 | C4: 0 | E4: 165.53 | F4: 302.06 | G4: (17, 25) | H4: ('E', 'A') | U4: FALSE
A5: 36_a | B5: =VLOOKUP(A5,PIPE!A:D,4,0) -> 325.83 | C5: 0 | E5: 77.08 | F5: 325.83 | G5: (10, 20) | H5: ('E', 'S') | U5: FALSE
A6: 63_a | B6: =VLOOKUP(A6,PIPE!A:D,4,0) -> 447.89 | C6: 0 | E6: 313.27 | F6: 447.89 | G6: (11, 17) | H6: ('E', 'E') | U6: FALSE
A7: 40_b | B7: =VLOOKUP(A7,PIPE!A:D,4,0) -> 326.42 | C7: 0 | E7: 209.77 | F7: 326.42 | G7: (21, 20) | H7: ('S', 'S') | U7: FALSE
A8: 59_a | B8: =VLOOKUP(A8,PIPE!A:D,4,0) -> 356.04 | C8: 0 | E8: 201.52 | F8: 356.04 | G8: (18, 20) | H8: ('E', 'S') | U8: FALSE
A9: 25_a | B9: =VLOOKUP(A9,PIPE!A:D,4,0) -> 297.08 | C9: 1 | D9: 38 | E9: 186.05 | F9: 297.08 | G9: (16, 27) | H9: ('E', 'A') | I9: 150 | J9: 83.176683 | K9: 238.75987 | L9: 83.176683 | M9: 25 | N9: 15.521725 | O9: 27.357529 | P9: 15.4939 | Q9: 1 | R9: 2045 | S9: 2045 | T9: 310.44075 | U9: FALSE | V9: 2 | W9: 0 | X9: 50 | Y9: 10 | Z9: 0 | AA9: 0 | AB9: 0 | AC9: 106.29502 | AD9: 110.85
A10: 37_b | B10: =VLOOKUP(A10,PIPE!A:D,4,0) -> 347.61 | C10: 0 | E10: 86.53 | F10: 347.61 | G10: (24, 5) | H10: ('S', 'K') | U10: FALSE
A11: 56_a | B11: =VLOOKUP(A11,PIPE!A:D,4,0) -> 263.83 | C11: 0 | E11: 41.05 | F11: 263.83 | G11: (15, 18) | H11: ('E', 'E') | U11: FALSE
A12: 31_a | B12: =VLOOKUP(A12,PIPE!A:D,4,0) -> 228.48 | C12: 1 | D12: 30 | E12: 85.68 | F12: 228.48 | G12: (15, 22) | H12: ('E', 'S') | I12: 150 | J12: 87.35104 | K12: 157.66753 | L12: 87.35104 | M12: 25 | N12: 18.302202 | O12: 25.322261 | P12: 15.341525 | Q12: 1 | R12: 2040 | S12: 2040 | T12: 250.32444 | U12: FALSE | V12: 2 | W12: 0 | X12: 50 | Y12: 10 | Z12: 0 | AA12: 0 | AB12: 53.516 | AC12: 69.76 | AD12: 72.712
A13: 58_a | B13: =VLOOKUP(A13,PIPE!A:D,4,0) -> 189.66 | C13: 0 | E13: 164.64 | F13: 189.66 | G13: (4, 24) | H13: ('K', 'S') | U13: FALSE
A14: 31_b | B14: =VLOOKUP(A14,PIPE!A:D,4,0) -> 228.48 | C14: 0 | E14: 142.8 | F14: 228.48 | G14: (22, 15) | H14: ('S', 'E') | U14: FALSE
A15: 23_a | B15: =VLOOKUP(A15,PIPE!A:D,4,0) -> 179.47 | C15: 0 | E15: 38.1 | F15: 179.47 | G15: (14, 21) | H15: ('E', 'S') | U15: FALSE
A16: 44_b | B16: =VLOOKUP(A16,PIPE!A:D,4,0) -> 348.87 | C16: 0 | E16: 258.27 | F16: 348.87 | G16: (23, 12) | H16: ('S', 'E') | U16: FALSE
A17: 43_a | B17: =VLOOKUP(A17,PIPE!A:D,4,0) -> 370.19 | C17: 0 | E17: 148.58 | F17: 370.19 | G17: (14, 17) | H17: ('E', 'E') | U17: FALSE
A18: 29_b | B18: =VLOOKUP(A18,PIPE!A:D,4,0) -> 78.12 | C18: 1 | D18: 18 | E18: 0 | F18: 78.12 | G18: (12, 5) | H18: ('E', 'K') | I18: 150 | J18: 150 | K18: 182.827 | L18: 150 | M18: 25 | N18: 25 | O18: 18.083504 | P18: 18.10041 | Q18: 0 | S18: 2030 | T18: 99.69535 | U18: FALSE | V18: 2 | W18: 0 | Z18: 14.468 | AA18: 24.83 | AB18: 25.8 | AC18: 26.413979 | AD18: 26.413979
A19: 13_b | B19: =VLOOKUP(A19,PIPE!A:D,4,0) -> 343.97 | C19: 1 | D19: 34 | E19: 183.25 | F19: 343.97 | G19: (22, 20) | H19: ('S', 'S') | I19: 178.00921 | J19: 72.949938 | K19: 195.23118 | L19: 72.949938 | M19: 25.086203 | N19: 12.702641 | O19: 22.227783 | P19: 12.206166 | Q19: 1 | R19: 2050 | S19: 2050 | T19: 244.00848 | U19: FALSE | V19: 2 | W19: 0 | X19: 50 | Y19: 10 | Z19: 0 | AA19: 0 | AB19: 0 | AC19: 0 | AD19: 46.8
A20: 43_b | B20: =VLOOKUP(A20,PIPE!A:D,4,0) -> 370.19 | C20: 0 | E20: 221.62 | F20: 370.19 | G20: (17, 14) | H20: ('E', 'E') | U20: FALSE
A21: 67_b | B21: =VLOOKUP(A21,PIPE!A:D,4,0) -> 110.44 | C21: 0 | E21: 85.34 | F21: 110.44 | G21: (26, 11) | H21: ('A', 'E') | U21: FALSE
A22: 51_a | B22: =VLOOKUP(A22,PIPE!A:D,4,0) -> 463.4 | C22: 0 | E22: 290.25 | F22: 463.4 | G22: (4, 12) | H22: ('K', 'E') | U22: FALSE
A23: 51_b | B23: =VLOOKUP(A23,PIPE!A:D,4,0) -> 463.4 | C23: 0 | E23: 173.15 | F23: 463.4 | G23: (12, 4) | H23: ('E', 'K') | U23: FALSE
A24: 3_b | B24: =VLOOKUP(A24,PIPE!A:D,4,0) -> 68.85 | C24: 1 | D24: 34 | E24: 57.79 | F24: 68.85 | G24: (17, 4) | H24: ('E', 'K') | I24: 150 | J24: 137.47836 | K24: 143.33677 | L24: 137.47836 | M24: 25 | N24: 21.998053 | O24: 21.839455 | P24: 21.759017 | Q24: 0 | S24: 2040 | T24: 81.692508 | U24: FALSE | V24: 2 | W24: 0 | Z24: 0 | AA24: 0 | AB24: 71.61 | AC24: 74.21 | AD24: 77.28
A25: 14_a | B25: =VLOOKUP(A25,PIPE!A:D,4,0) -> 222.05 | C25: 1 | D25: 26 | E25: 147.03 | F25: 222.05 | G25: (10, 21) | H25: ('E', 'S') | I25: 150 | J25: 68.230718 | K25: 136.22208 | L25: 68.230718 | M25: 25 | N25: 14.398163 | O25: 23.788198 | P25: 13.25316 | Q25: 1 | R25: 2040 | S25: 2040 | T25: 210.84234 | U25: FALSE | V25: 2 | W25: 0 | X25: 50 | Y25: 10 | Z25: 0 | AA25: 0 | AB25: 0 | AC25: 0 | AD25: 55.110648
A26: 37_a | B26: =VLOOKUP(A26,PIPE!A:D,4,0) -> 347.61 | C26: 0 | E26: 261.08 | F26: 347.61 | G26: (5, 24) | H26: ('K', 'S') | U26: FALSE
A27: 3_a | B27: =VLOOKUP(A27,PIPE!A:D,4,0) -> 68.85 | C27: 0 | E27: 11.06 | F27: 68.85 | G27: (4, 17) | H27: ('K', 'E') | U27: FALSE
A28: 58_b | B28: =VLOOKUP(A28,PIPE!A:D,4,0) -> 189.66 | C28: 0 | E28: 25.02 | F28: 189.66 | G28: (24, 4) | H28: ('S', 'K') | U28: FALSE
A29: 28_b | B29: =VLOOKUP(A29,PIPE!A:D,4,0) -> 496.16 | C29: 0 | E29: 288.59 | F29: 496.16 | G29: (16, 13) | H29: ('E', 'E') | U29: FALSE
A30: 67_a | B30: =VLOOKUP(A30,PIPE!A:D,4,0) -> 110.44 | C30: 1 | D30: 42 | E30: 12.05 | F30: 110.44 | G30: (11, 26) | H30: ('E', 'A') | I30: 150 | J30: 104.45679 | K30: 153.46191 | L30: 104.45679 | M30: 25 | N30: 22.20149 | O30: 22.189588 | P30: 22.206751 | Q30: 0 | S30: 2035 | T30: 216.29825 | U30: FALSE | V30: 2 | W30: 0 | Z30: 0 | AA30: 107.738 | AB30: 131.33 | AC30: 83.130979 | AD30: 71.959352
A31: 44_a | B31: =VLOOKUP(A31,PIPE!A:D,4,0) -> 348.87 | C31: 0 | E31: 90.6 | F31: 348.87 | G31: (12, 23) | H31: ('E', 'S') | U31: FALSE
A32: 34_b | B32: =VLOOKUP(A32,PIPE!A:D,4,0) -> 553.72 | C32: 0 | E32: 200.08 | F32: 553.72 | G32: (12, 11) | H32: ('E', 'E') | U32: FALSE
A33: 32_a | B33: =VLOOKUP(A33,PIPE!A:D,4,0) -> 345.18 | C33: 0 | E33: 303.66 | F33: 345.18 | G33: (5, 21) | H33: ('K', 'S') | U33: FALSE
A34: 64_a | B34: =VLOOKUP(A34,PIPE!A:D,4,0) -> 245.06 | C34: 0 | E34: 222.05 | F34: 245.06 | G34: (17, 24) | H34: ('E', 'S') | U34: FALSE
A35: 61_a | B35: =VLOOKUP(A35,PIPE!A:D,4,0) -> 233.52 | C35: 0 | E35: 229.52 | F35: 233.52 | G35: (18, 23) | H35: ('E', 'S') | U35: FALSE
A36: 62_b | B36: =VLOOKUP(A36,PIPE!A:D,4,0) -> 147.41 | C36: 0 | E36: 61.67 | F36: 147.41 | G36: (22, 10) | H36: ('S', 'E') | U36: FALSE
A37: 4_b | B37: =VLOOKUP(A37,PIPE!A:D,4,0) -> 151.35 | C37: 1 | D37: 38 | E37: 51.62 | F37: 151.35 | G37: (14, 6) | H37: ('E', 'K') | I37: 150 | J37: 100.14645 | K37: 205.93858 | L37: 100.14645 | M37: 25 | N37: 20.372963 | O37: 21.169234 | P37: 20.653032 | Q37: 0 | S37: 2035 | T37: 269.76181 | U37: FALSE | V37: 2 | W37: 0 | Z37: 0 | AA37: 50.73 | AB37: 49.362 | AC37: 54.12 | AD37: 56.32
A38: 16_a | B38: =VLOOKUP(A38,PIPE!A:D,4,0) -> 555.74 | C38: 0 | E38: 30.51 | F38: 555.74 | G38: (12, 27) | H38: ('E', 'A') | U38: FALSE
A39: 5_b | B39: =VLOOKUP(A39,PIPE!A:D,4,0) -> 80.23 | C39: 0 | E39: 14.54 | F39: 80.23 | G39: (23, 13) | H39: ('S', 'E') | U39: FALSE
A40: 54_a | B40: =VLOOKUP(A40,PIPE!A:D,4,0) -> 45.28 | C40: 1 | D40: 18 | E40: 37.23 | F40: 45.28 | G40: (5, 20) | H40: ('K', 'S') | I40: 182.827 | J40: 165.79097 | K40: 166.05856 | L40: 165.79097 | M40: 18.083504 | N40: 16.497934 | O40: 16.317469 | P40: 16.359963 | Q40: 0 | S40: 2030 | T40: 81.477722 | U40: TRUE | V40: 0.43 | W40: 30.554146 | Z40: 14.468 | AA40: 21.296 | AB40: 25.8 | AC40: 0 | AD40: 0
...

Sheet EUS - Sinks capacity evolution
A1: Sink node | B1: Initial capacity [Mt] | C1: 2030 capacity [Mt] | D1: 2035 capacity [Mt] | E1: 2040 capacity [Mt] | F1: 2045 capacity [Mt] | G1: 2050 capacity [Mt] | H1: Final capacity [Mt]
A2: 1 | B2: 1250 | C2: 1250 | D2: 1250 | E2: 1250 | F2: 1250 | G2: 1250 | H2: 1250
A3: 2 | B3: 3790 | C3: 3790 | D3: 3790 | E3: 3682.262 | F3: 3550.932 | G3: 3467.801 | H3: 3395.8417
A4: 3 | B4: 2100 | C4: 2100 | D4: 2100 | E4: 2100 | F4: 2100 | G4: 1993.705 | H4: 1882.855
A5: 19 | B5: 6655.37 | C5: 6655.37 | D5: 6655.37 | E5: 6655.37 | F5: 6655.37 | G5: 6655.37 | H5: 6655.37
A6: 20 | B6: 4571.37 | C6: 4571.37 | D6: 4556.902 | E6: 4535.606 | F6: 4509.806 | G6: 4509.806 | H6: 4509.806
A7: 21 | B7: 1372.72 | C7: 1372.72 | D7: 1372.72 | E7: 1372.72 | F7: 1372.72 | G7: 1372.72 | H7: 1336.2894
A8: 22 | B8: 2171.48 | C8: 2171.48 | D8: 2171.48 | E8: 2171.48 | F8: 2117.964 | G8: 2048.204 | H8: 1992.702
A9: 23 | B9: 4632.05 | C9: 4632.05 | D9: 4577.33 | E9: 4519.87 | F9: 4459.35 | G9: 4395.43 | H9: 4327.76
A10: 24 | B10: 1319.75 | C10: 1319.75 | D10: 1319.75 | E10: 1319.75 | F10: 1319.75 | G10: 1319.75 | H10: 1319.75

Sheet EUS - Utilization evolution
A1: Utilization node | B1: Utilization capacity [Mt] | C1: 2030 utilization [Mt] | D1: 2035 utilization [Mt] | E1: 2040 utilization [Mt] | F1: 2045 utilization [Mt] | G1: 2050 utilization [Mt]
A2: 4 | B2: 150 | C2: 0 | D2: 0 | E2: 71.61 | F2: 119.53902 | G2: 132.39065
A3: 5 | B3: 75 | C3: 0 | D3: 3.534 | E3: 0 | F3: 26.413979 | G3: 75
A4: 6 | B4: 75 | C4: 0 | D4: 50.73 | E4: 49.362 | F4: 54.12 | G4: 75

Sheet EUS - Cost breakdown
A1: Concept | B1: 2030 | C1: 2035 | D1: 2040 | E1: 2045 | F1: 2050 | G1: Total
A2: Capture cost | B2: 5288.0388 | C2: 13947.111 | D2: 17218.78 | E2: 17416.629 | F2: 15763.771 | G2: 69634.329
A3: Injection cost | B3: 453.1814 | C3: 925.01024 | D3: 1022.2958 | E3: 920.8521 | F3: 739.60992 | G3: 4060.9495
A4: CAPEX onshore pipe | B4: 333.14629 | C4: 486.06006 | D4: 542.85929 | E4: 708.11027 | F4: 364.9733 | G4: 2435.1492
A5: CAPEX onshore pipe (insulation only) | B5: 30.554146 | C5: 0 | D5: 0 | E5: 0 | F5: 0 | G5: 30.554146
A6: CAPEX offshore pipe | B6: 0 | C6: 98.422962 | D6: 0 | E6: 50.548483 | F6: 0 | G6: 148.97145
A7: CAPEX initial boosting stations | B7: 5561.7063 | C7: 8725.7608 | D7: 5010.4662 | E7: 2800.7361 | F7: 1727.8934 | G7: 23826.563
A8: CAPEX additional boosting stations | B8: 0 | C8: 0 | D8: 269.94239 | E8: 337.96589 | F8: 117.29307 | G8: 725.20135
A9: OPEX onshore pipe | B9: 43.309138 | C9: 96.016401 | D9: 143.35202 | E9: 200.71455 | F9: 199.5891 | G9: 682.98121
A10: OPEX onshore pipe (insulation only) | B10: 3.9720485 | C10: 3.010823 | D10: 2.282275 | E10: 1.7298952 | F10: 1.3113016 | G10: 12.306343
A11: OPEX offshore pipe | B11: 0 | C11: 12.795014 | D11: 9.6986662 | E11: 13.9229 | F11: 10.553524 | G11: 46.970104
A12: OPEX initial boosting stations | B12: 150.22829 | C12: 349.6284 | D12: 400.158 | E12: 378.83054 | F12: 333.82173 | G12: 1612.667
A13: OPEX additional boosting stations | B13: 0 | C13: 0 | D13: 6.9380719 | E13: 13.971691 | F13: 13.576459 | G13: 34.486222
... A19: TOTAL | B19: 58155.742 | C19: 47741.387 | D19: 33269.554 | E19: 23682.041 | F19: 13019.452 | G19: 175868.18

Sheet PIPE
A1: Pipeline identifier | B1: Node connection | C1: Connection type | D1: Longitude (km)
A2: 0_a | B2: (4, 5) | C2: ('K', 'K') | D2: 423.46
A3: 0_b | B3: (5, 4) | C3: ('K', 'K') | D3: 423.46
A4: 1_a | B4: (19, 27) | C4: ('S', 'A') | D4: 491.3
A5: 1_b | B5: (27, 19) | C5: ('A', 'S') | D5: 491.3
A6: 2_a | B6: (4, 11) | C6: ('K', 'E') | D6: 448.83
A7: 2_b | B7: (11, 4) | C7: ('E', 'K') | D7: 448.83
A8: 3_a | B8: (4, 17) | C8: ('K', 'E') | D8: 68.85
A9: 3_b | B9: (17, 4) | C9: ('E', 'K') | D9: 68.85
A10: 4_a | B10: (6, 14) | C10: ('K', 'E') | D10: 151.35
A11: 4_b | B11: (14, 6) | C11: ('E', 'K') | D11: 151.35
A12: 5_a | B12: (13, 23) | C12: ('E', 'S') | D12: 80.23
A13: 5_b | B13: (23, 13) | C13: ('S', 'E') | D13: 80.23
... A109: 71_b | B109: (9, 8) | C109: ('E', 'E') | D109: 192.08

Sheet HUS - Pipes
A1: Pipe ID | B1: Installed | C1: Diameter [inch] | D1: Distance until highest point [km] | E1: Longitude [km] | F1: Node connections | G1: Node types | H1: Initial pressure [bar] | I1: Pressure at highest point [bar] | J1: Final pressure [bar] | K1: Lowest pressure [bar] | L1: Initial temperature [°C] | M1: Temperature at critical pressure point [°C] | N1: Final temperature [°C] | O1: Lowest temperature [°C] | P1: Number of boosters | Q1: Booster installation year | R1: Installation Year | S1: Present Value Cost [M€] | T1: Insulated | U1: U-value [W/m^2/K] | V1: Insulation cost [M€] | W1: Booster delta pressure [bar] | X1: Booster delta temperature [°C] | Y1: Flow in 2030 | Z1: Flow in 2035 | AA1: Flow in 2040 | AB1: Flow in 2045 | AC1: Flow in 2050
A2: 17_a | B2: 0 | D2: 295.43 | E2: 336.49 | F2: (11, 25) | G2: ('E', 'A') | T2: FALSE
A3: 4_a | B3: 0 | D3: 99.73 | E3: 151.35 | F3: (6, 14) | G3: ('K', 'E') | T3: FALSE
A4: 49_a | B4: 0 | D4: 165.53 | E4: 302.06 | F4: (17, 25) | G4: ('E', 'A') | T4: FALSE
A5: 36_a | B5: 0 | D5: 77.08 | E5: 325.83 | F5: (10, 20) | G5: ('E', 'S') | T5: FALSE
A6: 63_a | B6: 0 | D6: 313.27 | E6: 447.89 | F6: (11, 17) | G6: ('E', 'E') | T6: FALSE
A7: 40_b | B7: 0 | D7: 209.77 | E7: 326.42 | F7: (21, 20) | G7: ('S', 'S') | T7: FALSE
A8: 59_a | B8: 0 | D8: 201.52 | E8: 356.04 | F8: (18, 20) | G8: ('E', 'S') | T8: FALSE
A9: 25_a | B9: 1 | C9: 38 | D9: 186.05 | E9: 297.08 | F9: (16, 27) | G9: ('E', 'A') | H9: 150 | I9: 83.176683 | J9: 238.75987 | K9: 83.176683 | L9: 25 | M9: 15.521725 | N9: 27.357529 | O9: 15.4939 | P9: 1 | Q9: 2045 | R9: 2045 | S9: 310.44075 | T9: FALSE | U9: 2 | V9: 0 | W9: 50 | X9: 10 | Y9: 0 | Z9: 0 | AA9: 0 | AB9: 96.357372 | AC9: 110.85
A10: 37_b | B10: 0 | D10: 86.53 | E10: 347.61 | F10: (24, 5) | G10: ('S', 'K') | T10: FALSE
A11: 56_a | B11: 0 | D11: 41.05 | E11: 263.83 | F11: (15, 18) | G11: ('E', 'E') | T11: FALSE
A12: 31_a | B12: 1 | C12: 30 | D12: 85.68 | E12: 228.48 | F12: (15, 22) | G12: ('E', 'S') | H12: 150 | I12: 87.35104 | J12: 157.66753 | K12: 87.35104 | L12: 25 | M12: 18.302202 | N12: 25.322261 | O12: 15.341525 | P12: 1 | Q12: 2040 | R12: 2040 | S12: 250.32444 | T12: FALSE | U12: 2 | V12: 0 | W12: 50 | X12: 10 | Y12: 0 | Z12: 0 | AA12: 0 | AB12: 0 | AC12: 73.04
A13: 58_a | B13: 0 | D13: 164.64 | E13: 189.66 | F13: (4, 24) | G13: ('K', 'S') | T13: FALSE
A14: 31_b | B14: 0 | D14: 142.8 | E14: 228.48 | F14: (22, 15) | G14: ('S', 'E') | T14: FALSE
A15: 23_a | B15: 0 | D15: 38.1 | E15: 179.47 | F15: (14, 21) | G15: ('E', 'S') | T15: FALSE
A16: 44_b | B16: 0 | D16: 258.27 | E16: 348.87 | F16: (23, 12) | G16: ('S', 'E') | T16: FALSE
A17: 43_a | B17: 0 | D17: 148.58 | E17: 370.19 | F17: (14, 17) | G17: ('E', 'E') | T17: FALSE
A18: 29_b | B18: 1 | C18: 18 | D18: 0 | E18: 78.12 | F18: (12, 5) | G18: ('E', 'K') | H18: 150 | I18: 150 | J18: 182.827 | K18: 150 | L18: 25 | M18: 25 | N18: 18.083504 | O18: 18.10041 | P18: 0 | R18: 2030 | S18: 99.69535 | T18: FALSE | U18: 2 | V18: 0 | Y18: 14.468 | Z18: 24.83 | AA18: 25.8 | AB18: 26.413979 | AC18: 26.413979
A19: 13_b | B19: 1 | C19: 34 | D19: 183.25 | E19: 343.97 | F19: (22, 20) | G19: ('S', 'S') | H19: 178.00921 | I19: 72.949938 | J19: 195.23118 | K19: 72.949938 | L19: 25.086203 | M19: 12.702641 | N19: 22.227783 | O19: 12.206166 | P19: 1 | Q19: 2050 | R19: 2050 | S19: 244.00848 | T19: FALSE | U19: 2 | V19: 0 | W19: 50 | X19: 10 | Y19: 0 | Z19: 0 | AA19: 0 | AB19: 0 | AC19: 78.8045
A20: 43_b | B20: 0 | D20: 221.62 | E20: 370.19 | F20: (17, 14) | G20: ('E', 'E') | T20: FALSE
A21: 67_b | B21: 0 | D21: 85.34 | E21: 110.44 | F21: (26, 11) | G21: ('A', 'E') | T21: FALSE
A22: 51_a | B22: 0 | D22: 290.25 | E22: 463.4 | F22: (4, 12) | G22: ('K', 'E') | T22: FALSE
A23: 51_b | B23: 0 | D23: 173.15 | E23: 463.4 | F23: (12, 4) | G23: ('E', 'K') | T23: FALSE
A24: 3_b | B24: 1 | C24: 34 | D24: 57.79 | E24: 68.85 | F24: (17, 4) | G24: ('E', 'K') | H24: 150 | I24: 137.47836 | J24: 143.33677 | K24: 137.47836 | L24: 25 | M24: 21.998053 | N24: 21.839455 | O24: 21.759017 | P24: 0 | R24: 2035 | S24: 107.77334 | T24: FALSE | U24: 2 | V24: 0 | Y24: 0 | Z24: 69.47 | AA24: 71.61 | AB24: 74.21 | AC24: 77.28
A25: 14_a | B25: 1 | C25: 26 | D25: 147.03 | E25: 222.05 | F25: (10, 21) | G25: ('E', 'S') | H25: 150 | I25: 68.230718 | J25: 136.22208 | K25: 68.230718 | L25: 25 | M25: 14.398163 | N25: 23.788198 | O25: 13.25316 | P25: 1 | Q25: 2040 | R25: 2040 | S25: 210.84234 | T25: FALSE | U25: 2 | V25: 0 | W25: 50 | X25: 10 | Y25: 0 | Z25: 0 | AA25: 52.99 | AB25: 55.110648 | AC25: 55.110648
A26: 37_a | B26: 0 | D26: 261.08 | E26: 347.61 | F26: (5, 24) | G26: ('K', 'S') | T26: FALSE
A27: 3_a | B27: 0 | D27: 11.06 | E27: 68.85 | F27: (4, 17) | G27: ('K', 'E') | T27: FALSE
A28: 58_b | B28: 1 | C28: 6 | D28: 25.02 | E28: 189.66 | F28: (24, 4) | G28: ('S', 'K') | H28: 187.70383 | I28: 149.00597 | J28: 150.87785 | K28: 149.00597 | L28: 35.737413 | M28: 19.727869 | N28: 19.81856 | O28: 19.726547 | P28: 0 | R28: 2045 | S28: 31.557135 | T28: FALSE | U28: 2 | V28: 0 | Y28: 0 | Z28: 0 | AA28: 0 | AB28: 0 | AC28: 0
A29: 28_b | B29: 0 | D29: 288.59 | E29: 496.16 | F29: (16, 13) | G29: ('E', 'E') | T29: FALSE
A30: 67_a | B30: 1 | C30: 42 | D30: 12.05 | E30: 110.44 | F30: (11, 26) | G30: ('E', 'A') | H30: 150 | I30: 104.45679 | J30: 153.46191 | K30: 104.45679 | L30: 25 | M30: 22.20149 | N30: 22.189588 | O30: 22.206751 | P30: 0 | R30: 2035 | S30: 216.29825 | T30: FALSE | U30: 2 | V30: 0 | Y30: 0 | Z30: 90.062 | AA30: 131.33 | AB30: 38.205128 | AC30: 0
A31: 44_a | B31: 0 | D31: 90.6 | E31: 348.87 | F31: (12, 23) | G31: ('E', 'S') | T31: FALSE
A32: 34_b | B32: 0 | D32: 200.08 | E32: 553.72 | F32: (12, 11) | G32: ('E', 'E') | T32: FALSE
A33: 32_a | B33: 0 | D33: 303.66 | E33: 345.18 | F33: (5, 21) | G33: ('K', 'S') | T33: FALSE
A34: 64_a | B34: 0 | D34: 222.05 | E34: 245.06 | F34: (17, 24) | G34: ('E', 'S') | T34: FALSE
A35: 61_a | B35: 0 | D35: 229.52 | E35: 233.52 | F35: (18, 23) | G35: ('E', 'S') | T35: FALSE
A36: 62_b | B36: 0 | D36: 61.67 | E36: 147.41 | F36: (22, 10) | G36: ('S', 'E') | T36: FALSE
A37: 4_b | B37: 1 | C37: 38 | D37: 51.62 | E37: 151.35 | F37: (14, 6) | G37: ('E', 'K') | H37: 150 | I37: 100.14645 | J37: 205.93858 | K37: 100.14645 | L37: 25 | M37: 20.372963 | N37: 21.169234 | O37: 20.653032 | P37: 0 | R37: 2040 | S37: 204.48032 | T37: FALSE | U37: 2 | V37: 0 | Y37: 0 | Z37: 0 | AA37: 52.26 | AB37: 54.12 | AC37: 56.32
A38: 16_a | B38: 0 | D38: 30.51 | E38: 555.74 | F38: (12, 27) | G38: ('E', 'A') | T38: FALSE
A39: 5_b | B39: 0 | D39: 14.54 | E39: 80.23 | F39: (23, 13) | G39: ('S', 'E') | T39: FALSE
A40: 54_a | B40: 1 | C40: 18 | D40: 37.23 | E40: 45.28 | F40: (5, 20) | G40: ('K', 'S') | H40: 182.827 | I40: 165.79097 | J40: 166.05856 | K40: 165.79097 | L40: 18.083504 | M40: 16.497934 | N40: 16.317469 | O40: 16.359963 | P40: 0 | R40: 2030 | S40: 81.477722 | T40: TRUE | U40: 0.43 | V40: 30.554146 | Y40: 14.468 | Z40: 12.904 | AA40: 21.202 | AB40: 0 | AC40: 0
...

Sheet HUS - Sinks capacity evolution
A1: Sink node | B1: Initial capacity [Mt] | C1: 2030 capacity [Mt] | D1: 2035 capacity [Mt] | E1: 2040 capacity [Mt] | F1: 2045 capacity [Mt] | G1: 2050 capacity [Mt] | H1: Final capacity [Mt]
A2: 1 | B2: 1250 | C2: 1250 | D2: 1250 | E2: 1250 | F2: 1250 | G2: 1250 | H2: 1250
A3: 2 | B3: 3790 | C3: 3790 | D3: 3790 | E3: 3699.938 | F3: 3568.608 | G3: 3530.4029 | H3: 3530.4029
A4: 3 | B4: 2100 | C4: 2100 | D4: 2100 | E4: 2100 | F4: 2100 | G4: 2003.6426 | H4: 1892.7926
A5: 19 | B5: 6655.37 | C5: 6655.37 | D5: 6655.37 | E5: 6655.37 | F5: 6655.37 | G5: 6655.37 | H5: 6655.37
A6: 20 | B6: 4571.37 | C6: 4571.37 | D6: 4556.902 | E6: 4543.998 | F6: 4522.796 | G6: 4522.796 | H6: 4522.796
A7: 21 | B7: 1372.72 | C7: 1372.72 | D7: 1372.72 | E7: 1372.72 | F7: 1372.72 | G7: 1372.72 | H7: 1372.72
A8: 22 | B8: 2171.48 | C8: 2171.48 | D8: 2171.48 | E8: 2171.48 | F8: 2171.48 | G8: 2142.97 | H8: 2119.1445
A9: 23 | B9: 4632.05 | C9: 4632.05 | D9: 4577.33 | E9: 4519.87 | F9: 4459.35 | G9: 4395.43 | H9: 4327.76
A10: 24 | B10: 1319.75 | C10: 1319.75 | D10: 1319.75 | E10: 1319.75 | F10: 1319.75 | G10: 1319.75 | H10: 1319.75

Sheet HUS - Utilization evolution
A1: Utilization node | B1: Utilization capacity [Mt] | C1: 2030 utilization [Mt] | D1: 2035 utilization [Mt] | E1: 2040 utilization [Mt] | F1: 2045 utilization [Mt] | G1: 2050 utilization [Mt]
A2: 4 | B2: 225 | C2: 0 | D2: 69.47 | E2: 71.61 | F2: 164.46487 | G2: 204.35
A3: 5 | B3: 112.5 | C3: 0 | D3: 11.926 | E3: 4.598 | F3: 26.413979 | G3: 107.0045
A4: 6 | B4: 112.5 | C4: 0 | D4: 0 | E4: 105.25 | F4: 109.23065 | G4: 111.43065

Sheet HUS - Cost breakdown
A1: Concept | B1: 2030 | C1: 2035 | D1: 2040 | E1: 2045 | F1: 2050 | G1: Total
A2: Capture cost | B2: 5288.0388 | C2: 14008.748 | D2: 17322.934 | E2: 17547.226 | F2: 15772.046 | G2: 69938.993
A3: Injection cost | B3: 453.1814 | C3: 795.71296 | D3: 803.20604 | E3: 646.92862 | F3: 437.06628 | G3: 3136.0953
A4: CAPEX onshore pipe | B4: 333.14629 | C4: 324.07159 | D4: 810.88219 | E4: 932.82582 | F4: 288.96156 | G4: 2689.8875
A5: CAPEX onshore pipe (insulation only) | B5: 30.554146 | C5: 0 | D5: 0 | E5: 0 | F5: 0 | G5: 30.554146
A6: CAPEX offshore pipe | B6: 0 | C6: 98.422962 | D6: 0 | E6: 50.548483 | F6: 0 | G6: 148.97145
A7: CAPEX initial boosting stations | B7: 5561.7063 | C7: 9647.4559 | D7: 3898.1774 | E7: 3548.357 | F7: 1398.8621 | G7: 24054.559
A8: CAPEX additional boosting stations | B8: 0 | C8: 0 | D8: 269.94239 | E8: 479.17437 | F8: 117.29307 | G8: 866.40983
A9: OPEX onshore pipe | B9: 43.309138 | C9: 74.957841 | D9: 162.23245 | E9: 244.2406 | F9: 222.70033 | G9: 747.44036
A10: OPEX onshore pipe (insulation only) | B10: 3.9720485 | C10: 3.010823 | D10: 2.282275 | E10: 1.7298952 | F10: 1.3113016 | G10: 12.306343
A11: OPEX offshore pipe | B11: 0 | C11: 12.795014 | D11: 9.6986662 | E11: 13.9229 | F11: 10.553524 | G11: 46.970104
A12: OPEX initial boosting stations | B12: 150.22829 | C12: 374.52888 | D12: 388.989 | E12: 390.5473 | F12: 333.82173 | G12: 1638.1152
A13: OPEX additional boosting stations | B13: 0 | C13: 0 | D13: 6.9380719 | E13: 17.608341 | F13: 16.326122 | G13: 40.872535
... A19: TOTAL | B19: 58155.742 | C19: 46221.381 | D19: 28552.211 | E19: 19891.854 | F19: 7505.6681 | G19: 160326.86

Sheet Network length per scenario
A1: Scenario | B1: 2030 | C1: 2035 | D1: 2040 | E1: 2045 | F1: 2050
A2: LUS | B2: 203.63 | C2: 408.65 | D2: 859.18 | E2: 1323.41 | F2: 2218.81
A3: EUS | B3: 203.63 | C3: 491.15 | D3: 1010.53 | E3: 1923.59 | F3: 2540.54
A4: HUS | B4: 203.63 | C4: 408.65 | D4: 1137.63 | E4: 2240.35 | F4: 2730.2
